Workbook

Sheet 1_Overview
A1: Pillar 1 Comprehensive Capability Mapping - v14.0 (FINAL)
A2: 199 strategic sub-capabilities · 22 tabs · ~6,200 rows · 6-batch build journey · 56 of 56 QA gates passed · Interactive Zennify-themed toggle cascade
A4: 1 - HOW TO USE THIS WORKBOOK
A5: Action | C5: How
A6: Quick start | B6: Open 17_Toggle_Control_Panel for the live cascade dashboard. Toggle any sub-cap in 2_Capability_Map column M (Zennify_Status) and watch dependent rows grey out across the workbook.
A7: Trace a capability | B7: Start at 2_Capability_Map. Pick a Sub_Cap_ID (e.g. P1C1.5.4). Filter every other tab by that ID - stories, L4 features, maturity, offerings, cross-pillar evidence are all keyed off it.
A8: Understand offerings | B8: Read 10_Productized_Offerings for offering catalog. Read 12_Offering_SubCap_Matrix for which sub-caps each offering addresses, with customized rationale + maturity lift per pair.
A9: Understand data products | B9: Read 11_Data_Products for the 36-module catalog across 7 categories. Read 13_DataProduct_SubCap_Matrix for direct sub-cap mappings.
A10: Find cross-pillar evidence | B10: Read 14_CrossPillar_Stories (742 stories from P2/P3/P4 with theme-derived P1 matches). Read 15_Theme_SubCap_Mapping for the theme-to-subcap rationale. Read 16_SubCap_CrossPillar_Coverage for per-sub-cap aggregate.
A11: Validate completeness | B11: Read 18_SubCap_Completeness_Profile for per-sub-cap completeness narrative. Read 19_Toggle_Cascade_Simulation for impact analysis. Read 20_Final_QA_Report for verification verdict across all 6 batches.
A12: Excel version requirement | B12: Excel 2021 or Excel 365 (XLOOKUP support). Workbook is set to fullCalcOnLoad so the toggle cascade evaluates the moment the file opens.
A14: 2 - ID SYSTEM (the keys that connect tabs)
A15: ID | B15: Format / Example | C15: What it identifies | D15: Tabs where it appears
A16: Sub_Cap_ID | B16: P1C{cat}.{l1}.{n} (e.g. P1C1.5.4) | C16: The MASTER KEY of the entire workbook. 199 unique IDs covering 4 categories (P1C1=Strategy & Vision; P1C2=Governance & Risk; P1C3=Innovation; P1C4=Change & Adoption). Sub-vertical variants use BK1/WM1/IC1/CU1/CL1/IB1 suffixes. | D16: 2_Capability_Map (col C); 3_User_Stories (col D); 5_L4 (col A); 6_Maturity (col A); 12 (col C); 13 (col C); 15 (col B as P1_Sub_Cap_ID); 16 (col A); 18 (col A); 19 (col A)
A17: Story_Key | B17: GEN-P1C{...}-M{X}-{NN} or JIRA-{key} | C17: Unique identifier for each user story. 1,302 P1-native stories in tab 3 plus 742 cross-pillar stories in tab 14 (originating in P2/P3/P4 but theme-matched to P1). | D17: 3_User_Stories (col A); 14_CrossPillar_Stories (col A)
A18: L3_ID | B18: L3-{vendor}-{platform} (e.g. L3-DB-LAKEHOUSE, L3-SF-FSC) | C18: 45 platform IDs covering Salesforce + Databricks + MuleSoft + nCino + Twilio. Each L3 is a distinct technology platform a sub-cap can be addressed by. | D18: 4_L3_Detailed (col A); 5_L4_Detailed (col C); 10_Productized_Offerings (col L: L3_Platforms_Used)
A19: Offering_ID | B19: OFF-{shortname} (e.g. OFF-DATA-MOD, OFF-FSC-PLATFORM) | C19: 13 offering IDs (9 priority + 4 supporting). Modern Managed Services is the wrap-around offering. | D19: 10_Productized_Offerings (col A); 12_Offering_SubCap_Matrix (col A)
A20: Module_ID | B20: DP-{cat}.{n} (e.g. DP-1.1, DP-7.3) | C20: 36 data product module IDs across 7 categories (Identity & Golden Record, Risk & Intelligence, Integration & Connectivity, Content & Document Intelligence, Journey & Engagement, Analytics & Insights, Governance & Quality). | D20: 11_Data_Products (col A); 13_DataProduct_SubCap_Matrix (col A)
A21: Theme | B21: 8 themes: governance, compliance_regulatory, strategy, data_governance, culture_change, kpi, innovation, risk | C21: Cross-pillar evidence themes. Each theme maps to 3-5 P1 sub-caps with customized rationale. | D21: 14_CrossPillar_Stories (col G: P1_Themes); 15_Theme_SubCap_Mapping (col A)
A22: Use_Case_ID | B22: UC-{archetype}-{n} | C22: 906 use cases organized into 22 archetypes. Each L4 feature is keyed to specific use case IDs. | D22: 5_L4_Detailed (col L: Use_Case_IDs_Using_Feature); 2_Capability_Map (col K: Use_Cases)
A23: Agent_ID / Construct_ID | B23: AGT-* / CON-* | C23: Agentforce agents (130) and validated platform constructs (37). Constructs are the anti-fabrication anchor - only catalog references that have been verified against vendor docs. | D23: 8_Agentforce_Agents_List; 9_Platform_Constructs_Library
A24: Zennify_Status | B24: Active / Inactive (toggle) | C24: The activation flag for each sub-cap. Default Active. Toggling drives the entire cascade across 9 dependent tabs + 2 aggregate tabs. | D24: 2_Capability_Map (col M, source); Effective_Status columns in tabs 3, 5, 6, 12, 13, 14, 15, 16, 18, 19; aggregate health columns in 10, 11; live counters in 17
A26: 3 - TAB INVENTORY (what each tab is, primary content, primary key)
A27: Tab | B27: What it is / what it stands for | C27: Content & primary keys | D27: Rows × Cols
A28: 1_Overview | B28: THIS TAB - navigation reference and how-to guide. | C28: Workbook orientation: ID system, tab inventory, linkage map, toggle system, batch journey summary. No data keys. | D28: 76 × 4
A29: 2_Capability_Map | B29: THE CANONICAL CAPABILITY DEFINITION. Source of truth for the 199 P1 sub-caps. Source of the toggle cascade. | C29: PRIMARY KEY: Sub_Cap_ID (col C). Other cols: Category (P1C1-P1C4), L1_Capability, Description, Solution_Type, Tier, Personas, L3 platforms addressing, L4 features available, Use Cases, Story refs, Zennify_Status (toggle, col M). | D29: 199 × 13
A30: 3_User_Stories_Catalogue | B30: P1-NATIVE USER STORIES. Stories specifically written for P1 capabilities. | C30: PRIMARY KEY: Story_Key (col A). Joins to: Sub_Cap_ID (col D). Other: Source_Type, Source_Ref, Use_Case_IDs, L4_Features_Used, Match_Confidence, Story_Summary, W/X/Y (Description/AC/SD), Implementation Steps, Deployment Checklist, Jira_Project_URL, Zennify_Effective_Status (cascade). | D30: 1,302 × 16
A31: 4_L3_Detailed | B31: PLATFORM CATALOG. The 45 L3 technology platforms used to address sub-caps. | C31: PRIMARY KEY: L3_ID (col A). Joins to: Sub_Cap_ID (col M: Linked_Sub_Caps_Top5). Other: Vendor, Platform_Name, Description, Detailed_Capabilities, Setup_Path, Prerequisites, Customization_Extension_Points, Common_Combinations, Linked_L4_Features, Reference_URL, Source_Evidence, Use_When. | D31: 45 × 16
A32: 5_L4_Detailed_Features | B32: L4 FEATURES (per sub-cap × use case). The most granular vendor-feature catalog. | C32: PRIMARY KEY: composite (Sub_Cap_ID + L3_Platform_ID + Feature_Name). Joins: Sub_Cap_ID (col A), L3_Platform_ID (col C), Use_Case_IDs_Using_Feature (col L). Other: Customization_Level, Detailed_Description, Configuration_Path, Validated_Customization_Patterns, Story_Refs_Using_Feature, Reference_URL, Is_Supplemental, Zennify_Effective_Status. | D32: 3,129 × 16
A33: 6_Maturity_Descriptors | B33: M1–M5 MATURITY PROGRESSION per sub-cap. | C33: PRIMARY KEY: Sub_Cap_ID (col A). Other: Category, L1_Capability, M1_Foundational, M1_Foundational_Features, M2_Developing, M2_Developing_Features, M3_Established_AI_Assisted, M3_Agentic_Features, M4_Advanced_Hybrid_Agentic, M4_Cross_System_Orchestration, M5_Transformational_Headless360, M5_Headless_360_Surfaces, Zennify_Effective_Status. | D33: 199 × 15
A34: 7_Product_Catalogue | B34: VENDOR COMPONENT CATALOG. 311 vendor products across the supporting ecosystem. | C34: Primary keys: Vendor + Product_Name. Used as cross-reference for L4 features and L3 platforms. No cascade column (this is a vendor reference, not sub-cap-keyed). | D34: 311 × 11
A35: 8_Agentforce_Agents_List | B35: AGENTFORCE AGENTS. 130 agents (Salesforce official + retail-bank library). | C35: Primary key: Agent_ID. Each agent has URL, persona, sub-vertical fit, and use case fit. | D35: 130 × 9
A36: 9_Platform_Constructs_Library | B36: VALIDATED PLATFORM CONSTRUCTS. The anti-fabrication anchor. | C36: Primary key: Construct_ID. Only contains constructs verified against vendor public docs - used to prevent hallucinated capability claims elsewhere in the catalog. | D36: 37 × 5
A37: 10_Productized_Offerings | B37: OFFERING CATALOG (BATCH 3). 13 offerings: 9 priority + 4 supporting; OFF-MMS is the wrap-around. | C37: PRIMARY KEY: Offering_ID (col A). Joins to: Sub_Cap_ID via tab 12 (Offering_SubCap_Matrix). Other: Category, Wrap_Around, Status, Overview, Industry_Challenge, Outcomes, Core_Capabilities, Tiers, Primary_Vendors, L3_Platforms_Used, Target_Personas, Reference_URL, Source_Evidence, Source_Doc_Section. Aggregate cascade columns: Total_Mapped_SubCaps, Active_Mapped_SubCaps, Linkage_Health_Pct (red→yellow→green color scale), Zennify_Effective_Status (Active/Partial/Inactive). | D37: 13 × 20
A38: 11_Data_Products | B38: DATA PRODUCT MODULE CATALOG (BATCH 3). 36 modules across 7 categories. | C38: PRIMARY KEY: Module_ID (col A) e.g. DP-1.1, DP-7.3. Joins via tab 13. Other: Category, Module_Name, Description, Typical_Pairing (Offerings), Validation_Strength, Reference_URL, Source_Doc_Section. Aggregate cascade: Total_Mapped, Active_Mapped, Linkage_Health_Pct, Effective_Status (with "No-Direct-Map" 4th state for modules without direct sub-cap mapping). | D38: 36 × 12
... A49: Z2_Plan_Revisions | B49: PLAN REVISIONS LOG across all 6 batches. | C49: 40 rows: each revision documents what changed, why (often citing user feedback), and forward-looking notes for future iterations. | D49: 40 × 5
A51: 4 - TAB LINKAGE MAP (which IDs connect which tabs)
A52: From tab | B52: Via key (and column) | C52: To tab | D52: Linkage purpose
A53: 2_Capability_Map | B53: Sub_Cap_ID (col C) | C53: 3_User_Stories_Catalogue (col D) | D53: Find all P1-native stories for a sub-cap
A54: 2_Capability_Map | B54: Sub_Cap_ID (col C) | C54: 5_L4_Detailed_Features (col A) | D54: Find all L4 features delivering a sub-cap (per use case)
...

Sheet 2_Capability_Map
A1: Category | B1: L1_Capability | C1: Sub_Cap_ID | D1: Sub_Cap_Name | E1: Description | F1: Solution_Type | G1: Tier | H1: Personas | I1: L3_Platforms_Addressing_SubCap | J1: L4_Features_Available | K1: Use_Cases | L1: Story_Refs_with_UC_Links | M1: Zennify_Status
A2: P1C1 | B2: Strategy Foundation & Alignment | C2: P1C1.1.1 | D2: Digital Strategy Document | E2: Documented digital transformation strategy with clear objectives, scope, and success criteria | F2: Hybrid | G2: T1 | H2: CIO, CDO, Chief Strategy Officer, Strategy & Planning Lead | I2: [L3-TBL-EMBED] Tableau Embedded Analytics (count: 5) [L3-SF-AGENTIC-SEARCH] Agentic Enterprise Search (count: 3) [L3-SF-AGENTFORCE] Salesforce Agentforce (count: 2) | J2: Agentforce Builder [L3: L3-SF-AGENTFORCE, Salesforce, Low-Code] Agentforce Topics & Actions [L3: L3-SF-AGENTFORCE, Salesforce, Configuration] Agentic Enterprise Search Engine [L3: L3-SF-AGENTIC-SEARCH, Salesforce, Configuration] Citations & Provenance Engine [L3: L3-SF-AGENTIC-SEARCH, Salesforce, Configuration] Search Skill in Agentforce [L3: L3-SF-AGENTIC-SEARCH, Salesforce, Configuration] Tableau Embedding API v3 [L3: L3-TBL-EMBED, Tableau, Code] VizQL Data Service (Headless Data API) [L3: L3-TBL-EMBED, Tableau, API] External Authorization Servers (EAS) [L3: L3-TBL-EMBED, Tableau, Configuration] Domain Allowlist for Embedding [L3: L3-TBL-EMBED, Tableau, Configuration] Unified Access Tokens (UATs) [L3: L3-TBL-EMBED, Tableau, Configuration] | K2: P1C1.1.1.UC1 [AI_AUTHOR]: AI-assisted authoring & maintenance of Digital Strategy Document P1C1.1.1.UC2 [WORKFLOW_CADENCE]: Workflow-orchestrated review & refresh cycle for Digital Strategy Document P1C1.1.1.UC3 [EXEC_DASHBOARD]: Real-time executive performance dashboard for Digital Strategy Document P1C1.1.1.UC4 [STAKEHOLDER_COMM]: Multi-channel stakeholder communication of Digital Strategy Document P1C1.1.1.UC5 [BOARD_PACK]: Automated board-pack assembly for Digital Strategy Document | L2: JIRA-BCFSC-1273 [src: jira_completed] → UCs: P1C1.1.1.UC2, P1C1.1.1.UC1 JIRA-BCFSC-1274 [src: jira_completed] → UCs: P1C1.1.1.UC2 JIRA-EBT-277 [src: jira_completed] → UCs: P1C1.1.1.UC2, P1C1.1.1.UC1 JIRA-EBT-378 [src: jira_completed] → UCs: P1C1.1.1.UC1, P1C1.1.1.UC3 JIRA-FFBI-760 [src: jira_completed] → UCs: P1C1.1.1.UC2 JIRA-IMA-223 [src: jira_completed] → UCs: P1C1.1.1.UC1 JIRA-MCUDA-13 [src: jira_completed] → UCs: P1C1.1.1.UC3 JIRA-MF-1073 [src: jira_completed] → UCs: P1C1.1.1.UC2, P1C1.1.1.UC1 JIRA-MF-1107 [src: jira_completed] → UCs: P1C1.1.1.UC2 JIRA-MF-235 [src: jira_completed] → UCs: P1C1.1.1.UC1 JIRA-MF-283 [src: jira_completed] → UCs: P1C1.1.1.UC1 JIRA-MF-288 [src: jira_completed] → UCs: P1C1.1.1.UC5 JIRA-MF-289 [src: jira_completed] → UCs: P1C1.1.1.UC1 JIRA-MF-290 [src: jira_completed] → UCs: P1C1.1.1.UC5 JIRA-MF-291 [src: jira_completed] → UCs: P1C1.1.1.UC2 JIRA-MF-294 [src: jira_completed] → UCs: P1C1.1.1.UC5 JIRA-MF-295 [src: jira_completed] → UCs: P1C1.1.1.UC1 JIRA-MF-324 [src: jira_completed] → UCs: P1C1.1.1.UC5, P1C1.1.1.UC1 JIRA-MF-325 [src: jira_completed] → UCs: P1C1.1.1.UC5, P1C1.1.1.UC1 JIRA-MF-670 [src: jira_completed] → UCs: P1C1.1.1.UC2 JIRA-NWFCU-274 [src: jira_completed] → UCs: P1C1.1.1.UC1, P1C1.1.1.UC3 JIRA-PF-501 [src: jira_completed] → UCs: P1C1.1.1.UC2 JIRA-PF-59 [src: jira_completed] → UCs: P1C1.1.1.UC2 JIRA-ZENN2-125 [src: jira_completed] → UCs: P1C1.1.1.UC2 JIRA-ZENN2-90 [src: jira_completed] → UCs: P1C1.1.1.UC1 | M2: Active
A3: P1C1 | B3: Strategy Foundation & Alignment | C3: P1C1.1.2 | D3: Business Alignment | E3: Alignment of digital strategy with overall business strategy and objectives | F3: Hybrid | G3: T1 | H3: CIO, CDO, Chief Strategy Officer, Strategy & Planning Lead | I3: [L3-TBL-EMBED] Tableau Embedded Analytics (count: 5) [L3-SF-AGENTIC-SEARCH] Agentic Enterprise Search (count: 3) [L3-SF-AGENTFORCE] Salesforce Agentforce (count: 2) | J3: Agentforce Builder [L3: L3-SF-AGENTFORCE, Salesforce, Low-Code] Agentforce Topics & Actions [L3: L3-SF-AGENTFORCE, Salesforce, Configuration] Agentic Enterprise Search Engine [L3: L3-SF-AGENTIC-SEARCH, Salesforce, Configuration] Citations & Provenance Engine [L3: L3-SF-AGENTIC-SEARCH, Salesforce, Configuration] Search Skill in Agentforce [L3: L3-SF-AGENTIC-SEARCH, Salesforce, Configuration] Tableau Embedding API v3 [L3: L3-TBL-EMBED, Tableau, Code] VizQL Data Service (Headless Data API) [L3: L3-TBL-EMBED, Tableau, API] External Authorization Servers (EAS) [L3: L3-TBL-EMBED, Tableau, Configuration] Domain Allowlist for Embedding [L3: L3-TBL-EMBED, Tableau, Configuration] Unified Access Tokens (UATs) [L3: L3-TBL-EMBED, Tableau, Configuration] | K3: P1C1.1.2.UC5 [BOARD_PACK]: Automated board-pack assembly for Business Alignment P1C1.1.2.UC3 [EXEC_DASHBOARD]: Real-time executive performance dashboard for Business Alignment P1C1.1.2.UC4 [STAKEHOLDER_COMM]: Multi-channel stakeholder communication of Business Alignment P1C1.1.2.UC1 [AI_AUTHOR]: AI-assisted authoring & maintenance of Business Alignment P1C1.1.2.UC2 [WORKFLOW_CADENCE]: Workflow-orchestrated review & refresh cycle for Business Alignment | L3: JIRA-MCUDA-13 [src: jira_completed] → UCs: P1C1.1.2.UC3 JIRA-ZENN2-125 [src: jira_completed] → UCs: P1C1.1.2.UC5 | M3: Active
A4: P1C1 | B4: Strategy Foundation & Alignment | C4: P1C1.1.3 | D4: Strategy Refresh Cadence | E4: Regular review and update cycle for digital strategy (annual minimum) | F4: Hybrid | G4: T1 | H4: CIO, CDO, Chief Strategy Officer, Strategy & Planning Lead | I4: [L3-TBL-EMBED] Tableau Embedded Analytics (count: 5) [L3-SF-AGENTIC-SEARCH] Agentic Enterprise Search (count: 3) [L3-SF-AGENTFORCE] Salesforce Agentforce (count: 2) | J4: Agentforce Builder [L3: L3-SF-AGENTFORCE, Salesforce, Low-Code] Agentforce Topics & Actions [L3: L3-SF-AGENTFORCE, Salesforce, Configuration] Agentic Enterprise Search Engine [L3: L3-SF-AGENTIC-SEARCH, Salesforce, Configuration] Citations & Provenance Engine [L3: L3-SF-AGENTIC-SEARCH, Salesforce, Configuration] Search Skill in Agentforce [L3: L3-SF-AGENTIC-SEARCH, Salesforce, Configuration] Tableau Embedding API v3 [L3: L3-TBL-EMBED, Tableau, Code] VizQL Data Service (Headless Data API) [L3: L3-TBL-EMBED, Tableau, API] External Authorization Servers (EAS) [L3: L3-TBL-EMBED, Tableau, Configuration] Domain Allowlist for Embedding [L3: L3-TBL-EMBED, Tableau, Configuration] Unified Access Tokens (UATs) [L3: L3-TBL-EMBED, Tableau, Configuration] | K4: P1C1.1.3.UC5 [BOARD_PACK]: Automated board-pack assembly for Strategy Refresh Cadence P1C1.1.3.UC3 [EXEC_DASHBOARD]: Real-time executive performance dashboard for Strategy Refresh Cadence P1C1.1.3.UC4 [STAKEHOLDER_COMM]: Multi-channel stakeholder communication of Strategy Refresh Cadence P1C1.1.3.UC1 [AI_AUTHOR]: AI-assisted authoring & maintenance of Strategy Refresh Cadence P1C1.1.3.UC2 [WORKFLOW_CADENCE]: Workflow-orchestrated review & refresh cycle for Strategy Refresh Cadence | L4: JIRA-IAMC-18 [src: jira_completed] → UCs: P1C1.1.3.UC5 | M4: Active
A5: P1C1 | B5: Strategy Foundation & Alignment | C5: P1C1.1.4 | D5: Vision Communication | E5: Clear communication of digital vision across all organizational levels | F5: Traditional | G5: T1 | H5: CIO, CDO, Chief Strategy Officer, Strategy & Planning Lead | I5: [L3-TBL-EMBED] Tableau Embedded Analytics (count: 5) [L3-SF-AGENTIC-SEARCH] Agentic Enterprise Search (count: 3) [L3-SF-AGENTFORCE] Salesforce Agentforce (count: 2) | J5: Agentforce Builder [L3: L3-SF-AGENTFORCE, Salesforce, Low-Code] Agentforce Topics & Actions [L3: L3-SF-AGENTFORCE, Salesforce, Configuration] Agentic Enterprise Search Engine [L3: L3-SF-AGENTIC-SEARCH, Salesforce, Configuration] Citations & Provenance Engine [L3: L3-SF-AGENTIC-SEARCH, Salesforce, Configuration] Search Skill in Agentforce [L3: L3-SF-AGENTIC-SEARCH, Salesforce, Configuration] Tableau Embedding API v3 [L3: L3-TBL-EMBED, Tableau, Code] VizQL Data Service (Headless Data API) [L3: L3-TBL-EMBED, Tableau, API] External Authorization Servers (EAS) [L3: L3-TBL-EMBED, Tableau, Configuration] Domain Allowlist for Embedding [L3: L3-TBL-EMBED, Tableau, Configuration] Unified Access Tokens (UATs) [L3: L3-TBL-EMBED, Tableau, Configuration] | K5: P1C1.1.4.UC4 [STAKEHOLDER_COMM]: Multi-channel stakeholder communication of Vision Communication P1C1.1.4.UC3 [EXEC_DASHBOARD]: Real-time executive performance dashboard for Vision Communication P1C1.1.4.UC5 [BOARD_PACK]: Automated board-pack assembly for Vision Communication P1C1.1.4.UC1 [AI_AUTHOR]: AI-assisted authoring & maintenance of Vision Communication P1C1.1.4.UC2 [WORKFLOW_CADENCE]: Workflow-orchestrated review & refresh cycle for Vision Communication | L5: JIRA-BB-475 [src: jira_completed] → UCs: P1C1.1.4.UC4 | M5: Active
A6: P1C1 | B6: Strategy Foundation & Alignment | C6: P1C1.1.5 | D6: Board Engagement | E6: Regular board-level engagement and reporting on digital strategy progress | F6: Traditional | G6: T1 | H6: CIO, CDO, Chief Strategy Officer, Strategy & Planning Lead | I6: [L3-TBL-EMBED] Tableau Embedded Analytics (count: 5) [L3-SF-AGENTIC-SEARCH] Agentic Enterprise Search (count: 3) [L3-SF-AGENTFORCE] Salesforce Agentforce (count: 2) | J6: Agentforce Builder [L3: L3-SF-AGENTFORCE, Salesforce, Low-Code] Agentforce Topics & Actions [L3: L3-SF-AGENTFORCE, Salesforce, Configuration] Agentic Enterprise Search Engine [L3: L3-SF-AGENTIC-SEARCH, Salesforce, Configuration] Citations & Provenance Engine [L3: L3-SF-AGENTIC-SEARCH, Salesforce, Configuration] Search Skill in Agentforce [L3: L3-SF-AGENTIC-SEARCH, Salesforce, Configuration] Tableau Embedding API v3 [L3: L3-TBL-EMBED, Tableau, Code] VizQL Data Service (Headless Data API) [L3: L3-TBL-EMBED, Tableau, API] External Authorization Servers (EAS) [L3: L3-TBL-EMBED, Tableau, Configuration] Domain Allowlist for Embedding [L3: L3-TBL-EMBED, Tableau, Configuration] Unified Access Tokens (UATs) [L3: L3-TBL-EMBED, Tableau, Configuration] | K6: P1C1.1.5.UC1 [AI_AUTHOR]: AI-assisted authoring & maintenance of Board Engagement P1C1.1.5.UC2 [WORKFLOW_CADENCE]: Workflow-orchestrated review & refresh cycle for Board Engagement P1C1.1.5.UC3 [EXEC_DASHBOARD]: Real-time executive performance dashboard for Board Engagement P1C1.1.5.UC4 [STAKEHOLDER_COMM]: Multi-channel stakeholder communication of Board Engagement P1C1.1.5.UC5 [BOARD_PACK]: Automated board-pack assembly for Board Engagement | L6: JIRA-FFBI-497 [src: jira_completed] → UCs: P1C1.1.5.UC1 JIRA-FFBI-511 [src: jira_completed] → UCs: P1C1.1.5.UC1 JIRA-FFBI-526 [src: jira_completed] → UCs: P1C1.1.5.UC1 JIRA-FFBI-527 [src: jira_completed] → UCs: P1C1.1.5.UC1 JIRA-FFBI-534 [src: jira_completed] → UCs: P1C1.1.5.UC2 JIRA-FFBI-535 [src: jira_completed] → UCs: P1C1.1.5.UC1 JIRA-INVYT-251 [src: jira_completed] → UCs: P1C1.1.5.UC1 JIRA-INVYT-68 [src: jira_completed] → UCs: P1C1.1.5.UC1, P1C1.1.5.UC3 JIRA-NCM-113 [src: jira_completed] → UCs: P1C1.1.5.UC1 JIRA-NWFCU-47 [src: jira_completed] → UCs: P1C1.1.5.UC2 JIRA-PF-652 [src: jira_completed] → UCs: P1C1.1.5.UC3, P1C1.1.5.UC1 JIRA-SILVERGATE-253 [src: jira_completed] → UCs: P1C1.1.5.UC1 JIRA-SILVERGATE-264 [src: jira_completed] → UCs: P1C1.1.5.UC3 JIRA-STLS-16 [src: jira_completed] → UCs: P1C1.1.5.UC3, P1C1.1.5.UC1 JIRA-STLS-179 [src: jira_completed] → UCs: P1C1.1.5.UC3 JIRA-STLS-180 [src: jira_completed] → UCs: P1C1.1.5.UC1 JIRA-STLS-181 [src: jira_completed] → UCs: P1C1.1.5.UC3 JIRA-STLS-193 [src: jira_completed] → UCs: P1C1.1.5.UC1 JIRA-STLS-79 [src: jira_completed] → UCs: P1C1.1.5.UC1 JIRA-STLS-81 [src: jira_completed] → UCs: P1C1.1.5.UC2 JIRA-STLS-84 [src: jira_completed] → UCs: P1C1.1.5.UC2 JIRA-STLS-85 [src: jira_completed] → UCs: P1C1.1.5.UC2 JIRA-STLS-86 [src: jira_completed] → UCs: P1C1.1.5.UC2 JIRA-STLS-87 [src: jira_completed] → UCs: P1C1.1.5.UC2 JIRA-ZENN2-88 [src: jira_completed] → UCs: P1C1.1.5.UC1 | M6: Active
A7: P1C1 | B7: Roadmap & Planning | C7: P1C1.2.1 | D7: Multi-Year Roadmap | E7: Documented 3-5 year digital transformation roadmap with milestones | F7: Hybrid | G7: T1 | H7: CIO, Program Director, Portfolio Manager, Architecture Lead | I7: [L3-TBL-EMBED] Tableau Embedded Analytics (count: 6) [L3-SF-AGENTIC-SEARCH] Agentic Enterprise Search (count: 4) [L3-SF-AGENTFORCE] Salesforce Agentforce (count: 2) | J7: Agentforce Builder [L3: L3-SF-AGENTFORCE, Salesforce, Low-Code] Agentforce Topics & Actions [L3: L3-SF-AGENTFORCE, Salesforce, Configuration] Agentic Enterprise Search Engine [L3: L3-SF-AGENTIC-SEARCH, Salesforce, Configuration] Federated Retrieval (Connected Sources) [L3: L3-SF-AGENTIC-SEARCH, Salesforce, API] Citations & Provenance Engine [L3: L3-SF-AGENTIC-SEARCH, Salesforce, Configuration] Search Skill in Agentforce [L3: L3-SF-AGENTIC-SEARCH, Salesforce, Configuration] Tableau Embedding API v3 [L3: L3-TBL-EMBED, Tableau, Code] Connected Apps with JWT Authentication [L3: L3-TBL-EMBED, Tableau, Configuration] VizQL Data Service (Headless Data API) [L3: L3-TBL-EMBED, Tableau, API] External Authorization Servers (EAS) [L3: L3-TBL-EMBED, Tableau, Configuration] Domain Allowlist for Embedding [L3: L3-TBL-EMBED, Tableau, Configuration] Unified Access Tokens (UATs) [L3: L3-TBL-EMBED, Tableau, Configuration] | K7: P1C1.2.1.UC2 [ALIGNMENT_LINK]: Strategy-to-execution linkage for Multi-Year Roadmap P1C1.2.1.UC4 [WORKFLOW_CADENCE]: Workflow-orchestrated review & refresh cycle for Multi-Year Roadmap P1C1.2.1.UC3 [EXEC_DASHBOARD]: Real-time executive performance dashboard for Multi-Year Roadmap P1C1.2.1.UC1 [AI_AUTHOR]: AI-assisted authoring & maintenance of Multi-Year Roadmap P1C1.2.1.UC5 [STAKEHOLDER_COMM]: Multi-channel stakeholder communication of Multi-Year Roadmap | L7: JIRA-BCFSC-1273 [src: jira_completed] → UCs: P1C1.2.1.UC4, P1C1.2.1.UC1 JIRA-BCFSC-1274 [src: jira_completed] → UCs: P1C1.2.1.UC4 JIRA-EBT-277 [src: jira_completed] → UCs: P1C1.2.1.UC4, P1C1.2.1.UC1 JIRA-EBT-378 [src: jira_completed] → UCs: P1C1.2.1.UC3, P1C1.2.1.UC1 JIRA-FFBI-760 [src: jira_completed] → UCs: P1C1.2.1.UC4 JIRA-IMA-223 [src: jira_completed] → UCs: P1C1.2.1.UC2 JIRA-MF-1073 [src: jira_completed] → UCs: P1C1.2.1.UC4, P1C1.2.1.UC1 JIRA-MF-1107 [src: jira_completed] → UCs: P1C1.2.1.UC4 JIRA-MF-235 [src: jira_completed] → UCs: P1C1.2.1.UC1 JIRA-MF-283 [src: jira_completed] → UCs: P1C1.2.1.UC4 JIRA-MF-288 [src: jira_completed] → UCs: P1C1.2.1.UC4 JIRA-MF-289 [src: jira_completed] → UCs: P1C1.2.1.UC4 JIRA-MF-290 [src: jira_completed] → UCs: P1C1.2.1.UC4 JIRA-MF-291 [src: jira_completed] → UCs: P1C1.2.1.UC4 JIRA-MF-294 [src: jira_completed] → UCs: P1C1.2.1.UC4 JIRA-MF-324 [src: jira_completed] → UCs: P1C1.2.1.UC1 JIRA-MF-325 [src: jira_completed] → UCs: P1C1.2.1.UC1 JIRA-MF-670 [src: jira_completed] → UCs: P1C1.2.1.UC4 JIRA-NWFCU-274 [src: jira_completed] → UCs: P1C1.2.1.UC3, P1C1.2.1.UC1 JIRA-PF-501 [src: jira_completed] → UCs: P1C1.2.1.UC4 JIRA-PF-504 [src: jira_completed] → UCs: P1C1.2.1.UC4 JIRA-PF-505 [src: jira_completed] → UCs: P1C1.2.1.UC2 JIRA-PF-508 [src: jira_completed] → UCs: P1C1.2.1.UC2 JIRA-PF-59 [src: jira_completed] → UCs: P1C1.2.1.UC2 JIRA-ZENN2-90 [src: jira_completed] → UCs: P1C1.2.1.UC2 | M7: Active
A8: P1C1 | B8: Roadmap & Planning | C8: P1C1.2.2 | D8: Initiative Prioritization | E8: Framework for prioritizing digital initiatives based on value and feasibility | F8: Hybrid | G8: T1 | H8: CIO, Program Director, Portfolio Manager, Architecture Lead | I8: [L3-TBL-EMBED] Tableau Embedded Analytics (count: 6) [L3-SF-AGENTIC-SEARCH] Agentic Enterprise Search (count: 4) [L3-SF-AGENTFORCE] Salesforce Agentforce (count: 2) | J8: Agentforce Builder [L3: L3-SF-AGENTFORCE, Salesforce, Low-Code] Agentforce Topics & Actions [L3: L3-SF-AGENTFORCE, Salesforce, Configuration] Agentic Enterprise Search Engine [L3: L3-SF-AGENTIC-SEARCH, Salesforce, Configuration] Federated Retrieval (Connected Sources) [L3: L3-SF-AGENTIC-SEARCH, Salesforce, API] Citations & Provenance Engine [L3: L3-SF-AGENTIC-SEARCH, Salesforce, Configuration] Search Skill in Agentforce [L3: L3-SF-AGENTIC-SEARCH, Salesforce, Configuration] Tableau Embedding API v3 [L3: L3-TBL-EMBED, Tableau, Code] Connected Apps with JWT Authentication [L3: L3-TBL-EMBED, Tableau, Configuration] VizQL Data Service (Headless Data API) [L3: L3-TBL-EMBED, Tableau, API] External Authorization Servers (EAS) [L3: L3-TBL-EMBED, Tableau, Configuration] Domain Allowlist for Embedding [L3: L3-TBL-EMBED, Tableau, Configuration] Unified Access Tokens (UATs) [L3: L3-TBL-EMBED, Tableau, Configuration] | K8: P1C1.2.2.UC2 [ALIGNMENT_LINK]: Strategy-to-execution linkage for Initiative Prioritization P1C1.2.2.UC5 [STAKEHOLDER_COMM]: Multi-channel stakeholder communication of Initiative Prioritization P1C1.2.2.UC4 [WORKFLOW_CADENCE]: Workflow-orchestrated review & refresh cycle for Initiative Prioritization P1C1.2.2.UC3 [EXEC_DASHBOARD]: Real-time executive performance dashboard for Initiative Prioritization P1C1.2.2.UC1 [AI_AUTHOR]: AI-assisted authoring & maintenance of Initiative Prioritization | L8: JIRA-IMA-118 [src: jira_completed] → UCs: P1C1.2.2.UC4 | M8: Active
A9: P1C1 | B9: Roadmap & Planning | C9: P1C1.2.3 | D9: Resource Planning | E9: Resource allocation and capacity planning for digital initiatives | F9: Hybrid | G9: T1 | H9: CIO, Program Director, Portfolio Manager, Architecture Lead | I9: [L3-TBL-EMBED] Tableau Embedded Analytics (count: 6) [L3-SF-AGENTIC-SEARCH] Agentic Enterprise Search (count: 4) [L3-SF-AGENTFORCE] Salesforce Agentforce (count: 2) | J9: Agentforce Builder [L3: L3-SF-AGENTFORCE, Salesforce, Low-Code] Agentforce Topics & Actions [L3: L3-SF-AGENTFORCE, Salesforce, Configuration] Agentic Enterprise Search Engine [L3: L3-SF-AGENTIC-SEARCH, Salesforce, Configuration] Federated Retrieval (Connected Sources) [L3: L3-SF-AGENTIC-SEARCH, Salesforce, API] Citations & Provenance Engine [L3: L3-SF-AGENTIC-SEARCH, Salesforce, Configuration] Search Skill in Agentforce [L3: L3-SF-AGENTIC-SEARCH, Salesforce, Configuration] Tableau Embedding API v3 [L3: L3-TBL-EMBED, Tableau, Code] Connected Apps with JWT Authentication [L3: L3-TBL-EMBED, Tableau, Configuration] VizQL Data Service (Headless Data API) [L3: L3-TBL-EMBED, Tableau, API] External Authorization Servers (EAS) [L3: L3-TBL-EMBED, Tableau, Configuration] Domain Allowlist for Embedding [L3: L3-TBL-EMBED, Tableau, Configuration] Unified Access Tokens (UATs) [L3: L3-TBL-EMBED, Tableau, Configuration] | K9: P1C1.2.3.UC3 [EXEC_DASHBOARD]: Real-time executive performance dashboard for Resource Planning P1C1.2.3.UC2 [ALIGNMENT_LINK]: Strategy-to-execution linkage for Resource Planning P1C1.2.3.UC1 [AI_AUTHOR]: AI-assisted authoring & maintenance of Resource Planning P1C1.2.3.UC5 [STAKEHOLDER_COMM]: Multi-channel stakeholder communication of Resource Planning P1C1.2.3.UC4 [WORKFLOW_CADENCE]: Workflow-orchestrated review & refresh cycle for Resource Planning | L9: PUB-P1C1.2.3.UC3 [src: use_case_derived_public_validated] → UCs: P1C1.2.3.UC3 PUB-P1C1.2.3.UC2 [src: use_case_derived_public_validated] → UCs: P1C1.2.3.UC2 PUB-P1C1.2.3.UC1 [src: use_case_derived_public_validated] → UCs: P1C1.2.3.UC1 PUB-P1C1.2.3.UC5 [src: use_case_derived_public_validated] → UCs: P1C1.2.3.UC5 PUB-P1C1.2.3.UC4 [src: use_case_derived_public_validated] → UCs: P1C1.2.3.UC4 | M9: Active
A10: P1C1 | B10: Roadmap & Planning | C10: P1C1.2.4 | D10: Dependency Management | E10: Identification and management of cross-initiative dependencies | F10: Hybrid | G10: T1 | H10: CIO, Program Director, Portfolio Manager, Architecture Lead | I10: [L3-TBL-EMBED] Tableau Embedded Analytics (count: 6) [L3-SF-AGENTIC-SEARCH] Agentic Enterprise Search (count: 4) [L3-SF-AGENTFORCE] Salesforce Agentforce (count: 2) | J10: Agentforce Builder [L3: L3-SF-AGENTFORCE, Salesforce, Low-Code] Agentforce Topics & Actions [L3: L3-SF-AGENTFORCE, Salesforce, Configuration] Agentic Enterprise Search Engine [L3: L3-SF-AGENTIC-SEARCH, Salesforce, Configuration] Federated Retrieval (Connected Sources) [L3: L3-SF-AGENTIC-SEARCH, Salesforce, API] Citations & Provenance Engine [L3: L3-SF-AGENTIC-SEARCH, Salesforce, Configuration] Search Skill in Agentforce [L3: L3-SF-AGENTIC-SEARCH, Salesforce, Configuration] Tableau Embedding API v3 [L3: L3-TBL-EMBED, Tableau, Code] Connected Apps with JWT Authentication [L3: L3-TBL-EMBED, Tableau, Configuration] VizQL Data Service (Headless Data API) [L3: L3-TBL-EMBED, Tableau, API] External Authorization Servers (EAS) [L3: L3-TBL-EMBED, Tableau, Configuration] Domain Allowlist for Embedding [L3: L3-TBL-EMBED, Tableau, Configuration] Unified Access Tokens (UATs) [L3: L3-TBL-EMBED, Tableau, Configuration] | K10: P1C1.2.4.UC2 [ALIGNMENT_LINK]: Strategy-to-execution linkage for Dependency Management P1C1.2.4.UC3 [EXEC_DASHBOARD]: Real-time executive performance dashboard for Dependency Management P1C1.2.4.UC1 [AI_AUTHOR]: AI-assisted authoring & maintenance of Dependency Management P1C1.2.4.UC5 [STAKEHOLDER_COMM]: Multi-channel stakeholder communication of Dependency Management P1C1.2.4.UC4 [WORKFLOW_CADENCE]: Workflow-orchestrated review & refresh cycle for Dependency Management | L10: PUB-P1C1.2.4.UC2 [src: use_case_derived_public_validated] → UCs: P1C1.2.4.UC2 PUB-P1C1.2.4.UC3 [src: use_case_derived_public_validated] → UCs: P1C1.2.4.UC3 PUB-P1C1.2.4.UC1 [src: use_case_derived_public_validated] → UCs: P1C1.2.4.UC1 PUB-P1C1.2.4.UC5 [src: use_case_derived_public_validated] → UCs: P1C1.2.4.UC5 PUB-P1C1.2.4.UC4 [src: use_case_derived_public_validated] → UCs: P1C1.2.4.UC4 | M10: Active
A11: P1C1 | B11: Roadmap & Planning | C11: P1C1.2.5 | D11: Budget Alignment | E11: Alignment of digital investment budget with strategic priorities | F11: Hybrid | G11: T1 | H11: CIO, Program Director, Portfolio Manager, Architecture Lead | I11: [L3-TBL-EMBED] Tableau Embedded Analytics (count: 6) [L3-SF-AGENTIC-SEARCH] Agentic Enterprise Search (count: 4) [L3-SF-AGENTFORCE] Salesforce Agentforce (count: 2) | J11: Agentforce Builder [L3: L3-SF-AGENTFORCE, Salesforce, Low-Code] Agentforce Topics & Actions [L3: L3-SF-AGENTFORCE, Salesforce, Configuration] Agentic Enterprise Search Engine [L3: L3-SF-AGENTIC-SEARCH, Salesforce, Configuration] Federated Retrieval (Connected Sources) [L3: L3-SF-AGENTIC-SEARCH, Salesforce, API] Citations & Provenance Engine [L3: L3-SF-AGENTIC-SEARCH, Salesforce, Configuration] Search Skill in Agentforce [L3: L3-SF-AGENTIC-SEARCH, Salesforce, Configuration] Tableau Embedding API v3 [L3: L3-TBL-EMBED, Tableau, Code] Connected Apps with JWT Authentication [L3: L3-TBL-EMBED, Tableau, Configuration] VizQL Data Service (Headless Data API) [L3: L3-TBL-EMBED, Tableau, API] External Authorization Servers (EAS) [L3: L3-TBL-EMBED, Tableau, Configuration] Domain Allowlist for Embedding [L3: L3-TBL-EMBED, Tableau, Configuration] Unified Access Tokens (UATs) [L3: L3-TBL-EMBED, Tableau, Configuration] | K11: P1C1.2.5.UC4 [WORKFLOW_CADENCE]: Workflow-orchestrated review & refresh cycle for Budget Alignment P1C1.2.5.UC3 [EXEC_DASHBOARD]: Real-time executive performance dashboard for Budget Alignment P1C1.2.5.UC2 [ALIGNMENT_LINK]: Strategy-to-execution linkage for Budget Alignment P1C1.2.5.UC1 [AI_AUTHOR]: AI-assisted authoring & maintenance of Budget Alignment P1C1.2.5.UC5 [STAKEHOLDER_COMM]: Multi-channel stakeholder communication of Budget Alignment | L11: PUB-P1C1.2.5.UC4 [src: use_case_derived_public_validated] → UCs: P1C1.2.5.UC4 PUB-P1C1.2.5.UC3 [src: use_case_derived_public_validated] → UCs: P1C1.2.5.UC3 PUB-P1C1.2.5.UC2 [src: use_case_derived_public_validated] → UCs: P1C1.2.5.UC2 PUB-P1C1.2.5.UC1 [src: use_case_derived_public_validated] → UCs: P1C1.2.5.UC1 PUB-P1C1.2.5.UC5 [src: use_case_derived_public_validated] → UCs: P1C1.2.5.UC5 | M11: Active
A12: P1C1 | B12: Segment Strategy | C12: P1C1.3.1 | D12: Customer Segment Definition | E12: Clear definition of target customer segments for digital engagement | F12: Hybrid | G12: T1 | H12: CMO, Customer Strategy Lead, LOB Heads (Banking/Wealth/Insurance), Product Manager | I12: [L3-TBL-EMBED] Tableau Embedded Analytics (count: 6) [L3-SF-DATA-CLOUD] Salesforce Data Cloud (Data 360) (count: 5) [L3-SF-AGENTIC-SEARCH] Agentic Enterprise Search (count: 5) [L3-SF-CRMA] Salesforce CRM Analytics (count: 3) [L3-SF-SLACK] Slack (count: 3) [L3-NCINO-CONSUMER] nCino Consumer Lending (count: 2) | J12: CRM Analytics Dashboards [L3: L3-SF-CRMA, Salesforce, Configuration] Einstein Discovery [L3: L3-SF-CRMA, Salesforce, Configuration] CRM Analytics Story Builder [L3: L3-SF-CRMA, Salesforce, Configuration] Zero-Copy Architecture [L3: L3-SF-DATA-CLOUD, Salesforce, Configuration] Agentic Setup and Data Management [L3: L3-SF-DATA-CLOUD, Salesforce, Configuration] Intelligent Segmentation [L3: L3-SF-DATA-CLOUD, Salesforce, Configuration] AI-Calculated Insights [L3: L3-SF-DATA-CLOUD, Salesforce, Configuration] Data 360 Activation APIs [L3: L3-SF-DATA-CLOUD, Salesforce, API] Slack Lists [L3: L3-SF-SLACK, Salesforce, Configuration] Slack Canvas [L3: L3-SF-SLACK, Salesforce, Configuration] Slack AI [L3: L3-SF-SLACK, Salesforce, OOB] Agentic Enterprise Search Engine [L3: L3-SF-AGENTIC-SEARCH, Salesforce, Configuration] Federated Retrieval (Connected Sources) [L3: L3-SF-AGENTIC-SEARCH, Salesforce, API] Permission-Aware Result Filter [L3: L3-SF-AGENTIC-SEARCH, Salesforce, Configuration] Citations & Provenance Engine [L3: L3-SF-AGENTIC-SEARCH, Salesforce, Configuration] Search Skill in Agentforce [L3: L3-SF-AGENTIC-SEARCH, Salesforce, Configuration] Auto-Decisioning Rules Engine [L3: L3-NCINO-CONSUMER, nCino, Configuration] Credit Bureau Integration [L3: L3-NCINO-CONSUMER, nCino, Configuration] Tableau Embedding API v3 [L3: L3-TBL-EMBED, Tableau, Code] Connected Apps with JWT Authentication [L3: L3-TBL-EMBED, Tableau, Configuration] VizQL Data Service (Headless Data API) [L3: L3-TBL-EMBED, Tableau, API] External Authorization Servers (EAS) [L3: L3-TBL-EMBED, Tableau, Configuration] Domain Allowlist for Embedding [L3: L3-TBL-EMBED, Tableau, Configuration] Unified Access Tokens (UATs) [L3: L3-TBL-EMBED, Tableau, Configuration] | K12: P1C1.3.1.UC4 [SELF_SERVICE_PORTAL]: Persona-based self-service portal for Customer Segment Definition P1C1.3.1.UC1 [EXEC_DASHBOARD]: Real-time executive performance dashboard for Customer Segment Definition P1C1.3.1.UC2 [DECISION_SUPPORT]: AI decision support at point of action for Customer Segment Definition P1C1.3.1.UC3 [EXTERNAL_BENCHMARK]: Peer benchmarking & calibration for Customer Segment Definition P1C1.3.1.UC5 [ALIGNMENT_LINK]: Strategy-to-execution linkage for Customer Segment Definition | L12: JIRA-AN-19 [src: jira_completed] → UCs: P1C1.3.1.UC5 JIRA-MF-448 [src: jira_completed] → UCs: P1C1.3.1.UC4, P1C1.3.1.UC1 JIRA-MOE-17 [src: jira_completed] → UCs: P1C1.3.1.UC1, P1C1.3.1.UC5 JIRA-NAVEBANK-288 [src: jira_completed] → UCs: P1C1.3.1.UC4 JIRA-PF-746 [src: jira_completed] → UCs: P1C1.3.1.UC1 JIRA-ZBFQS20-79 [src: jira_completed] → UCs: P1C1.3.1.UC1 JIRA-ZBFQS20-82 [src: jira_completed] → UCs: P1C1.3.1.UC1 | M12: Active
... A200: P1C1 | B200: Technology Strategy | C200: P1C1.5.8 | D200: Sustainable Cloud | E200: Selection and use of sustainable cloud providers | F200: Headless | G200: T1 | H200: CTO, Chief Architect, Cloud Architect, IT Strategy Lead | I200: [L3-SF-AGENTFORCE] Salesforce Agentforce (count: 2) [L3-SF-AGENTFORCE-FS] Agentforce for Financial Services (count: 1) | J200: Agentforce Builder [L3: L3-SF-AGENTFORCE, Salesforce, Low-Code] Agentforce Topics & Actions [L3: L3-SF-AGENTFORCE, Salesforce, Configuration] Embedded Compliance Controls [L3: L3-SF-AGENTFORCE-FS, Salesforce, Configuration] | K200: P1C1.5.8.UC5 [COVERAGE_MONITORING]: Coverage gap monitoring for Sustainable Cloud P1C1.5.8.UC4 [DECISION_SUPPORT]: AI decision support at point of action for Sustainable Cloud P1C1.5.8.UC3 [ALIGNMENT_LINK]: Strategy-to-execution linkage for Sustainable Cloud P1C1.5.8.UC2 [EXEC_DASHBOARD]: Real-time executive performance dashboard for Sustainable Cloud P1C1.5.8.UC1 [AI_AUTHOR]: AI-assisted authoring & maintenance of Sustainable Cloud | L200: PUB-P1C1.5.8.UC5 [src: use_case_derived_public_validated] → UCs: P1C1.5.8.UC5 PUB-P1C1.5.8.UC4 [src: use_case_derived_public_validated] → UCs: P1C1.5.8.UC4 PUB-P1C1.5.8.UC3 [src: use_case_derived_public_validated] → UCs: P1C1.5.8.UC3 PUB-P1C1.5.8.UC2 [src: use_case_derived_public_validated] → UCs: P1C1.5.8.UC2 PUB-P1C1.5.8.UC1 [src: use_case_derived_public_validated] → UCs: P1C1.5.8.UC1 | M200: Active

Sheet 3_User_Stories_Catalogue
A1: Story_Key | B1: Source_Type | C1: Source_Ref | D1: Sub_Cap_ID | E1: Sub_Cap_Name | F1: Use_Case_IDs | G1: L4_Features_Used | H1: Match_Confidence | I1: Story_Summary | J1: W_Description | K1: X_Acceptance_Criteria | L1: Y_Solution_Design | M1: Implementation_Steps | N1: Deployment_Checklist | O1: Jira_Project_URL | P1: Zennify_Effective_Status
A2: GEN-P1C2.7.1-M1M2-01 | B2: gen_stories_v1 | C2: gen_stories_export.xlsx row for GEN-P1C2.7.1-M1M2-01 | D2: P1C2.7.1 | E2: Regulatory Change Management | F2: P1C2.7.1.UC4, P1C2.7.1.UC2 | H2: HIGH | I2: As a Compliance Manager, I want to create and track regulatory changes in a central registry so that all stakeholders have visibility into upcoming and implemented regulatory requirements. | J2: Organizations need a structured way to document regulatory changes, their effective dates, and impacted business areas. This foundation enables regulatory teams to systematically track requirements and communicate them downstream. Without this, changes are communicated ad-hoc, leading to inconsistent implementation and gaps. | K2: AC1: Given a new regulatory requirement, When I create a record for the regulatory change, Then the system captures the regulation name, effective date, description, and primary impact area. AC2: Given a regulatory change record exists, When a compliance team member searches for changes by regulation type or date, Then they can view all matching records with full details. AC3: Given a regulatory change affects multiple financial products, When I link the related Financial Accounts to the change, Then the relationship is maintained for impact tracking. AC4: Given a regulatory change is created with an assigned owner, When the record is saved, Then the owner receives notification with the change summary. AC5: Given a regulatory change reaches its effective date, When the status is updated to Active, Then all assigned stakeholders receive notification that the requirement is now in effect. | L2: Overview: This story establishes the foundational regulatory change tracking system using Salesforce's core platform. It creates a central repository where compliance teams can systematically log regulatory requirements, link them to affected business areas and stakeholders, and trigger automated notifications at key lifecycle points. This enables visibility and accountability without requiring custom development. Object & Field Setup: - Create custom object [REGULATORY_CHANGE_OBJECT] to store regulatory requirement details - Add required fields: Regulation Name, Effective Date, Description, Impact Area (picklist), Status (picklist: Pending Implementation / In Progress / Active / Completed), Owner (lookup to User) - Create lookup field to link [REGULATORY_CHANGE_OBJECT] to impacted Financial Accounts - Create list view [REGULATORY_CHANGES_BY_EFFECTIVE_DATE] sorted by Effective Date to surface upcoming requirements - Create list view [REGULATORY_CHANGES_BY_STATUS] filtered by Status for progress tracking Automation: - Create Record-Triggered Flow [NOTIFY_OWNER_ON_REGULATORY_CHANGE_CREATION]: Triggers when a new record is created, sends email notification to Owner with regulation summary and deadline - Create Record-Triggered Flow [NOTIFY_STAKEHOLDERS_ON_ACTIVE_STATUS]: Triggers when Status changes to Active, sends notifications to all assigned stakeholders indicating implementation is required - Create validation rule [REGULATORY_CHANGE_REQUIRED_FIELDS]: Enforces Regulation Name, Effective Date, and Status are always populated before save Access & Permissions: - Create permission set [REGULATORY_CHANGE_MANAGER]: Grants Create, Read, Edit, Delete on [REGULATORY_CHANGE_OBJECT] - Create permission set [REGULATORY_CHANGE_VIEWER]: Grants Read-only access to [REGULATORY_CHANGE_OBJECT] - Create sharing rule to automatically share records with assigned owner - Assign [REGULATORY_CHANGE_MANAGER] to compliance/governance team; [REGULATORY_CHANGE_VIEWER] to business unit leaders | P2: {=IFERROR(XLOOKUP(D2, '2_Capability_Map'!$C$2:$C$200, '2_Capability_Map'!$M$2:$M$200, "Active"), "Active")} -> Active
A3: GEN-P1C2.7.1-M1M2-02 | B3: gen_stories_v1 | C3: gen_stories_export.xlsx row for GEN-P1C2.7.1-M1M2-02 | D3: P1C2.7.1 | E3: Regulatory Change Management | F3: P1C2.7.1.UC4, P1C2.7.1.UC2 | H3: HIGH | I3: As a Change Manager, I want to assign and track stakeholder ownership for each regulatory change so that accountability is clear and implementation progress can be monitored. | J3: Each regulatory change impacts different organizational units and roles. Assigning clear owners and linking secondary stakeholders creates accountability chains and enables the compliance team to track progress against each change. This is essential for moving from ad-hoc reactive compliance to managed change. | K3: AC1: Given a regulatory change affects multiple business units, When I assign owners to each impacted unit, Then each owner receives assignment notification with their implementation responsibility. AC2: Given a regulatory change has an assigned owner, When the owner updates the Status field, Then the system logs timestamp and owner name with the status change. AC3: Given multiple stakeholders are involved in implementing a single change, When I link secondary stakeholders to the regulatory change record, Then each stakeholder can view the change from their record relationships. AC4: Given a compliance manager needs to track ownership, When they filter the regulatory change list by owner or status, Then they see only relevant records with ownership accountability. AC5: Given a regulatory change owner is assigned, When they do not update status within 30 days of effective date, Then the system auto-generates a reminder task assigned to them. | L3: Overview: This story adds stakeholder and ownership management on top of the core regulatory change registry. It creates accountability by assigning named owners and tracking their progress, and creates relationship links to secondary stakeholders. Automation ensures timely reminders when implementation falls behind. This transforms regulatory changes from broadcast announcements into tracked, accountable work assignments. Object & Field Setup: - Add lookup field to [REGULATORY_CHANGE_OBJECT]: Primary Owner (links to User) - Add many-to-many junction object [REGULATORY_CHANGE_STAKEHOLDER] with lookup to [REGULATORY_CHANGE_OBJECT] and lookup to User to enable multiple stakeholders per change - Add field: Last Status Update Date (auto-populated by flow) - Add field: Days Since Active (formula to calculate days since Status = Active) Automation: - Create Record-Triggered Flow [ASSIGN_OWNER_AND_NOTIFY]: Triggers when Primary Owner is populated, sends email to owner with ownership acknowledgment and deadline - Create Record-Triggered Flow [LOG_STATUS_CHANGE]: Triggers on Status field update, logs the old value, new value, user, and timestamp to a status history child object - Create Record-Triggered Flow [OVERRIDE_ON_LATE_IMPLEMENTATION]: Triggers when a record has Status = Active for 30+ days, auto-generates a task [REGULATORY_CHANGE_FOLLOWUP_TASK] assigned to owner Access & Permissions: - Extend [REGULATORY_CHANGE_MANAGER] permission set to include CRUD on [REGULATORY_CHANGE_STAKEHOLDER] junction object - Create formula-based sharing to give all linked stakeholders Read access to the regulatory change record - Ensure each owner sees only the regulatory changes assigned to them via role-based sharing (or create row-level sharing rules) | P3: {=IFERROR(XLOOKUP(D3, '2_Capability_Map'!$C$2:$C$200, '2_Capability_Map'!$M$2:$M$200, "Active"), "Active")} -> Active
A4: GEN-P1C2.7.1-M1M2-03 | B4: gen_stories_v1 | C4: gen_stories_export.xlsx row for GEN-P1C2.7.1-M1M2-03 | D4: P1C2.7.1 | E4: Regulatory Change Management | F4: P1C2.7.1.UC4, P1C2.7.1.UC2 | H4: HIGH | I4: As a Compliance Communications Lead, I want to automate notifications and communications so that all relevant stakeholders are informed promptly when regulatory changes are created, updated, or approach their effective dates. | J4: Manual communication of regulatory changes is slow, inconsistent, and error-prone. Automated notifications via Salesforce alerts ensure the right people get the right information at the right time. This creates a consistent communication cadence, reduces reliance on manual emails, and ensures no stakeholder is left out of critical regulatory deadlines. | K4: AC1: Given a regulatory change is created, When the owner is assigned, Then an automated notification is sent with the regulation name, effective date, and owner assignment confirmation. AC2: Given a regulatory change has an effective date approaching, When 30 days remain before the date, Then automated alerts are sent to the primary owner and all linked stakeholders. AC3: Given a regulatory change status is updated, When the change is marked as Active, Then all stakeholders receive a notification indicating the requirement is now in effect and implementation is mandatory. AC4: Given a regulatory change has linked reference documents, When stakeholders receive a notification, Then the notification includes direct links to access those documents. AC5: Given a stakeholder is added to a regulatory change, When they are linked to the record, Then they receive a notification with full context about their role in the implementation. | L4: Overview: This story adds structured, automated communication workflows on top of the ownership model. Using Record-Triggered Flows and Alerts, it ensures stakeholders receive timely notifications at key regulatory change lifecycle points (creation, pre-effective-date, active, etc.). This eliminates gaps in communication and creates an audit trail of who was notified when. Automation: - Create Record-Triggered Flow [ALERT_30_DAYS_BEFORE_EFFECTIVE]: Triggers 30 days before Effective Date, sends email alert to Primary Owner and all stakeholders with change summary and action required - Create Record-Triggered Flow [ALERT_AT_EFFECTIVE_DATE]: Triggers on day of Effective Date, sends notification to all stakeholders that requirement is now active - Create Record-Triggered Flow [NOTIFY_ON_STAKEHOLDER_ADD]: Triggers when a stakeholder is added to [REGULATORY_CHANGE_STAKEHOLDER] junction, sends welcome notification with change context - Create Workflow Alert [REGULATORY_CHANGE_CREATION_ALERT]: Sends notification to compliance leadership when a critical regulatory change is created - Create process or flow to append notification history to the regulatory change record for audit trail Access & Permissions: - Ensure notification recipients have Read access to [REGULATORY_CHANGE_OBJECT] and linked Financial Accounts - Grant [REGULATORY_CHANGE_MANAGER] permission to create alerts and modify automation rules - Create a [NOTIFICATION_HISTORY_CHILD_OBJECT] to log all communications sent, with Create/Read permissions for auditors | P4: {=IFERROR(XLOOKUP(D4, '2_Capability_Map'!$C$2:$C$200, '2_Capability_Map'!$M$2:$M$200, "Active"), "Active")} -> Active
A5: GEN-P1C2.7.1-M1M2-04 | B5: gen_stories_v1 | C5: gen_stories_export.xlsx row for GEN-P1C2.7.1-M1M2-04 | D5: P1C2.7.1 | E5: Regulatory Change Management | F5: P1C2.7.1.UC4, P1C2.7.1.UC5 | H5: HIGH | I5: As a Process Owner, I want to identify and document which business processes and financial products are impacted by regulatory changes so that implementation teams can plan and execute their work scope. | J5: Understanding regulatory impact requires mapping requirements to affected business processes, products, and systems. Documenting this impact assessment upfront prevents rework, ensures comprehensive implementation, and gives implementation teams the information they need to plan. This transforms regulatory changes from abstract requirements into concrete implementation work. | K5: AC1: Given a regulatory change requires updates to business processes or financial products, When I create an impact assessment record linked to the regulatory change, Then it captures affected processes, product types, impacted systems, and estimated effort hours. AC2: Given an impact assessment identifies affected Financial Accounts or product types, When I link those records to the assessment, Then the system maintains relationships for downstream execution tracking. AC3: Given a regulatory change impacts multiple business processes, When I document those in the impact assessment, Then stakeholders can see the full scope of work required in their area. AC4: Given an impact assessment is completed by a process owner, When a compliance manager reviews it, Then they can approve or request refinement without modifying the original regulatory change record. AC5: Given multiple regulatory changes are in flight, When I view the impact assessments, Then I can see cross-change dependencies and potential conflicts in implementation approach. | L5: Overview: This story adds impact assessment and work-scope definition on top of the core regulatory change tracking. It creates a structured, linked object to map regulatory requirements to affected business processes, products, and systems. This enables implementation teams to understand their specific obligations without having to infer them from the regulatory requirement, and allows compliance leadership to identify conflicts or dependencies across multiple concurrent changes. Object & Field Setup: - Create custom object [REGULATORY_IMPACT_ASSESSMENT] with lookup to [REGULATORY_CHANGE_OBJECT] - Add fields: Affected Processes (multi-select), Affected Product Types (multi-select), Impacted Systems, Estimated Effort Hours, Assessment Status (picklist: Draft / In Review / Approved) - Create lookup field from [REGULATORY_IMPACT_ASSESSMENT] to Financial Account to map affected products - Add relationship to Action Plans object to enable creation of implementation work from the assessment - Create list view [REGULATORY_IMPACT_BY_PROCESS] to view all changes impacting a given business process Automation: - Create Record-Triggered Flow [COPY_IMPACT_TO_CHANGE_SUMMARY]: When impact assessment is marked Approved, updates the regulatory change record's Impact Area and linked accounts - Create Record-Triggered Flow [NOTIFY_COMPLIANCE_ON_ASSESSMENT_CREATION]: When an impact assessment is created, notifies assigned compliance reviewer Access & Permissions: - Create permission set [IMPACT_ASSESSMENT_AUTHOR]: Grants Create, Read, Edit on [REGULATORY_IMPACT_ASSESSMENT] to process owners - Create permission set [IMPACT_ASSESSMENT_REVIEWER]: Grants Read, Edit (approval field only) to compliance managers - Use field-level security to prevent process owners from modifying the regulatory change record directly | P5: {=IFERROR(XLOOKUP(D5, '2_Capability_Map'!$C$2:$C$200, '2_Capability_Map'!$M$2:$M$200, "Active"), "Active")} -> Active
A6: GEN-P1C2.7.1-M3-01 | B6: gen_stories_v1 | C6: gen_stories_export.xlsx row for GEN-P1C2.7.1-M3-01 | D6: P1C2.7.1 | E6: Regulatory Change Management | F6: P1C2.7.1.UC4, P1C2.7.1.UC1 | G6: OmniStudio, OmniScript | H6: HIGH | I6: As a Business Unit Leader, I want a self-service portal where I can view my assigned regulatory changes, understand specific impacts, and confirm my team's implementation completion so that adoption is transparent and doesn't require manual status reporting. | J6: An Experience Cloud portal for regulatory changes enables stakeholders to self-serve information and status updates, reducing administrative burden on the compliance team. It supports transparency and decentralized adoption tracking by allowing teams to confirm their implementation status without compliance staff collecting manual updates. This scales adoption management across the organization. | K6: AC1: Given a stakeholder logs into the regulatory change portal, When they view their dashboard, Then they see only regulatory changes assigned to their business unit or role. AC2: Given a regulatory change is displayed on the portal, When a stakeholder clicks to view details, Then they see the requirement, implementation deadline, their team's specific impact, and linked guidance documents. AC3: Given a stakeholder has completed implementation in their area, When they access the regulatory change, Then they can click a button to mark it as Complete for My Area and optionally add completion notes. AC4: Given a stakeholder marks a change as complete, When the action is submitted, Then the compliance team's dashboard is updated in real-time to show completion status. AC5: Given a regulatory change has linked training materials or reference documents, When a stakeholder accesses the portal, Then they can download or view these resources directly without leaving the portal. | L6: Overview: This story adds a self-service Experience Cloud portal to the M1M2 regulatory change management system. Business unit leaders can view their assigned changes, drill into impacts specific to their area, and confirm completion without waiting for manual status collection. This creates real-time visibility for the compliance team while reducing administrative overhead and empowering business units to self-manage their compliance obligations. Object & Field Setup: - Add field to [REGULATORY_CHANGE_OBJECT]: Completion Status by Area (multi-select or related list of completion records) - Create custom object [REGULATORY_CHANGE_COMPLETION] with lookup to [REGULATORY_CHANGE_OBJECT], lookup to User/Business Unit, date field, and notes field OmniStudio Configuration: - Create FlexCard [REGULATORY_CHANGE_SUMMARY_CARD] displaying regulation name, effective date, owner, and primary impact area - Create FlexCard [REGULATORY_CHANGE_ACTIONS_CARD] with action buttons: View Full Details, Mark Complete, Download Documents - Create OmniScript [REGULATORY_CHANGE_COMPLETION_FORM] to collect completion confirmation and optional notes when stakeholder marks change as complete - Create LWC or FlexCard [ASSIGNED_CHANGES_LIST] showing all regulatory changes assigned to the logged-in user's business unit Experience Cloud: - Create Experience Cloud community [REGULATORY_CHANGE_PORTAL] with custom theme and branding - Add pages: My Regulatory Changes (list of assigned), Change Details (record view with completion form), Help Center (documentation) - Configure access control to ensure business unit members see only their assigned changes (use org-wide defaults and sharing rules) Automation: - Create Record-Triggered Flow [UPDATE_COMPLETION_ON_FORM_SUBMISSION]: When [REGULATORY_CHANGE_COMPLETION] record is created, updates the parent [REGULATORY_CHANGE_OBJECT] completion tracking and notifies compliance manager | P6: {=IFERROR(XLOOKUP(D6, '2_Capability_Map'!$C$2:$C$200, '2_Capability_Map'!$M$2:$M$200, "Active"), "Active")} -> Active
